<?xml version="1.0"?>
<robot name="cobra">

  <!-- Mateirals -->
  <material name="blue">
    <color rgba="0 0.5 0.5 1"/>
  </material>

  <material name="yellow">
    <color rgba="1 0.7 0 1"/>
  </material>

  <!-- World -->
  <link name="world"/>
  <joint name="world_to_bottom" type="fixed">
    <parent link="world"/>
    <child link="bottom"/>
    <origin xyz="0 0 0.3" rpy="0 0 0"/>
  </joint>

  <!-- Base -->
  <link name="bottom">
    <visual>
      <origin xyz="0 0 0" rpy="0 0 0"/>
      <geometry>
        <box size="0.8 0.8 0.3"/>
      </geometry>
      <material name="blue">
      </material>
    </visual>
    <collision>
      <origin xyz="0 0 0" rpy="0 0 0"/>
      <geometry>
        <box size="0.8 0.8 0.3"/>
      </geometry>
    </collision>
    <inertial>
      <mass value="1.0"/>
      <origin xyz="0 0 0" rpy="0 0 0"/>
      <inertia ixx="0.054" iyy="0.054" izz="0.096" ixy="0" ixz="0" iyz="0"/>
    </inertial>
  </link>

  <!-- Pedestal -->
  <link name="pedestal">
    <visual>
      <origin xyz="0 0 0.3" rpy="0 0 0"/>
      <geometry>
        <box size="0.6 0.5 0.65"/>
      </geometry>
      <material name="blue">
      </material>
    </visual>
    <collision>
      <origin xyz="0 0 0.3" rpy="0 0 0"/>
      <geometry>
        <box size="0.6 0.5 0.65"/>
      </geometry>
    </collision>
    <inertial>
      <mass value="0.2"/>
      <origin xyz="0 0 0.325" rpy="0 0 0"/>
      <inertia ixx="0.055" iyy="0.064" izz="0.027" ixy="0" ixz="0" iyz="0"/>
    </inertial>
  </link>

  <joint name="bottom_to_pedestal" type="revolute">
    <axis xyz="0 0 1"/>
    <limit effort="1000.0" lower="0.0" upper="3.14" velocity="1.0"/>
    <parent link="bottom"/>
    <child link="pedestal"/>
    <origin xyz="0 0 0" rpy="0 0 0"/>
  </joint>

  <!-- Arm -->
  <link name="arm">
    <visual>
      <origin xyz="0 0.06 0.6" rpy="0 0 0"/>
      <geometry>
        <box size="0.4 0.5 1.6"/>
      </geometry>
      <material name="blue">
      </material>
    </visual>
    <collision>
      <origin xyz="0 0.06 0.6" rpy="0 0 0"/>
      <geometry>
        <box size="0.4 0.5 1.6"/>
      </geometry>
    </collision>
    <inertial>
      <mass value="0.3"/>
      <origin xyz="0 0.06 0.6" rpy="0 0 0"/>
      <inertia ixx="0.067" iyy="0.066" izz="0.013" ixy="0" ixz="0" iyz="0"/>
    </inertial>
  </link>

  <joint name="pedestal_to_arm" type="revolute">
  
    <axis xyz="0 1 0"/>
    <limit effort="1000.0" lower="0.0" upper="2.18166157" velocity="1.0"/>  
    <parent link="pedestal"/>
    <child link="arm"/>
    <origin rpy="0 -1.13446401 0" xyz="0 0 0.4"/>
  </joint>

  <!-- Forearm -->
  <link name="forearm">
    <visual>
      <origin xyz="-0.1 0 0.3" rpy="0 0 0"/>
      <geometry>
        <box size="0.4 0.5 1.25"/>
      </geometry>
      <material name="blue">
      </material>
    </visual>
    <collision>
      <origin xyz="-0.1 0 0.3" rpy="0 0 0"/>
      <geometry>
        <box size="0.4 0.5 1.25"/>
      </geometry>
    </collision>
    <inertial>
      <mass value="0.2"/>
      <origin xyz="-0.1 0 0.3" rpy="0 0 0"/>
      <inertia ixx="0.048" iyy="0.050" izz="0.015" ixy="0" ixz="0" iyz="0"/>
    </inertial>
  </link>

  <joint name="arm_to_forearm" type="revolute">
    <axis xyz="0 -1 0"/>
    <limit effort="1000.0" lower="0.0" upper="2.70526034" velocity="1.0"/>
    <parent link="arm"/>
    <child link="forearm"/>
    <origin rpy="0 2.70526034 0" xyz="0 0 1.2"/>
  </joint>

  <!-- Platform -->
  <link name="platform">
    <visual>
      <origin xyz="0 0 0" rpy="0 0 0"/>
      <geometry>
        <box size="0.03 0.5 0.5"/>
      </geometry>
      <material name="blue">
      </material>
    </visual>
    <collision>
      <origin xyz="0 0 0" rpy="0 0 0"/>
      <geometry>
        <box size="0.03 0.5 0.5"/>
      </geometry>
    </collision>
    <inertial>
      <mass value="0.01"/>
      <origin xyz="0 0 0.25" rpy="0 0 0"/>
      <inertia ixx="0.004" iyy="0.005" izz="0.004" ixy="0" ixz="0" iyz="0"/>
    </inertial>
  </link>

  <joint name="forearm_to_platform" type="fixed">
    <parent link="forearm"/>
    <child link="platform"/>
    <origin xyz="-0.2 0 0.6" rpy="0 0 0"/>
  </joint>

  <!-- Left Gripper -->
  <link name="left_gripper">
    <visual>
      <origin xyz="-0.1 -0.05 0.15" rpy="0 0 0"/>
      <geometry>
        <box size="0.03 0.1 0.6"/> 
      </geometry>
      <material name="yellow">
      </material>
    </visual>
    <collision>
      <geometry>
        <box size="0.03 0.1 0.3"/>
      </geometry>
    </collision>
    <inertial>
      <mass value="0.01"/>
      <origin xyz="0 0 0" rpy="0 0 0"/>
      <inertia ixx="0.004" iyy="0.005" izz="0.004" ixy="0" ixz="0" iyz="0"/>
    </inertial>
  </link>

  <joint name="left_gripper_joint" type="revolute">
    <axis xyz="1 0 0"/>
    <limit effort="1000" lower="0.0" upper="0.523599" velocity="1.0"/>
    <parent link="platform"/>
    <child link="left_gripper"/>
    <origin xyz="-0.1 -0.15 0.15" rpy="0 0 0"/>
  </joint>

    <!-- Left Tip of Gripper -->
  <link name="left_tip_gripper">
    <visual>
      <origin xyz="0 0 0.12" rpy="0 0 0"/>
      <geometry>
        <box size="0.03 0.1 0.3"/> 
      </geometry>
      <material name="yellow">
      </material>
    </visual>
    <collision>
      <geometry>
        <box size="0.03 0.1 0.3"/>
      </geometry>
    </collision>
    <inertial>
      <mass value="0.01"/>
      <origin xyz="0 0 0" rpy="0 0 0"/>
      <inertia ixx="0.004" iyy="0.005" izz="0.004" ixy="0" ixz="0" iyz="0"/>
    </inertial>
  </link>

  <joint name="left_tip_gripper_joint" type="fixed">
    <axis xyz="1 0 0"/>
    <parent link="left_gripper"/>
    <child link="left_tip_gripper"/>
    <origin xyz="-0.1 -0.05 0.45" rpy="-0.6 0 0"/>
  </joint>

      <!-- Left point of Tip -->
  <link name="left_point_tip_gripper">
    <visual>
      <origin xyz="0 0.005 0.04" rpy="0 0 0"/>
      <geometry>
        <box size="0.03 0.1 0.1"/> 
      </geometry>
      <material name="yellow">
      </material>
    </visual>
    <collision>
      <geometry>
        <box size="0.03 0.1 0.1"/>
      </geometry>
    </collision>
    <inertial>
      <mass value="0.01"/>
      <origin xyz="0 0 0" rpy="0 0 0"/>
      <inertia ixx="0.004" iyy="0.005" izz="0.004" ixy="0" ixz="0" iyz="0"/>
    </inertial>
  </link>

  <joint name="left_point_tip_gripper_joint" type="fixed">
    <axis xyz="1 0 0"/>
    <parent link="left_tip_gripper"/>
    <child link="left_point_tip_gripper"/>
    <origin xyz="0 0 0.25" rpy="0.6 0 0"/>
  </joint>

  <!-- Right Gripper -->
  <link name="right_gripper">
    <visual>
      <origin xyz="-0.1 0.05 0.15" rpy="0 0 0"/>
      <geometry>
        <box size="0.03 0.1 0.6"/>
      </geometry>
      <material name="yellow">
      </material>
    </visual>
    <collision>
      <geometry>
        <box size="0.03 0.1 0.3"/>
      </geometry>
    </collision>
    <inertial>
      <mass value="0.01"/>
      <origin xyz="0 0 0" rpy="0 0 0"/>
      <inertia ixx="0.004" iyy="0.005" izz="0.004" ixy="0" ixz="0" iyz="0"/>
    </inertial>
  </link>
  
  <joint name="right_gripper_joint" type="revolute">
    <axis xyz="-1 0 0"/>
    <limit effort="1000" lower="0.0" upper="0.523599" velocity="1.0"/>
    <parent link="platform"/>
    <child link="right_gripper"/>
    <origin xyz="-0.1 0.15 0.15" rpy="0 0 0"/>
  </joint>

    <!-- Right Tip of Gripper -->
  <link name="right_tip_gripper">
    <visual>
      <origin xyz="0 0 0.12" rpy="0 0 0"/>
      <geometry>
        <box size="0.03 0.1 0.3"/> 
      </geometry>
      <material name="yellow">
      </material>
    </visual>
    <collision>
      <geometry>
        <box size="0.03 0.1 0.3"/>
      </geometry>
    </collision>
    <inertial>
      <mass value="0.01"/>
      <origin xyz="0 0 0" rpy="0 0 0"/>
      <inertia ixx="0.004" iyy="0.005" izz="0.004" ixy="0" ixz="0" iyz="0"/>
    </inertial>
  </link>

  <joint name="right_tip_gripper_joint" type="fixed">
    <axis xyz="1 0 0"/>
    <parent link="right_gripper"/>
    <child link="right_tip_gripper"/>
    <origin xyz="-0.1 0.05 0.45" rpy="0.6  0 0"/>
  </joint>

      <!-- Right point of Tip -->
  <link name="right_point_tip_gripper">
    <visual>
      <origin xyz="0 -0.005 0.04" rpy="0 0 0"/>
      <geometry>
        <box size="0.03 0.1 0.1"/> 
      </geometry>
      <material name="yellow">
      </material>
    </visual>
    <collision>
      <geometry>
        <box size="0.03 0.1 0.1"/>
      </geometry>
    </collision>
    <inertial>
      <mass value="0.1"/>
      <origin xyz="0 0 0" rpy="0 0 0"/>
      <inertia ixx="0.004" iyy="0.005" izz="0.004" ixy="0" ixz="0" iyz="0"/>
    </inertial>
  </link>

  <joint name="right_point_tip_gripper_joint" type="fixed">
    <axis xyz="1 0 0"/>
    <parent link="right_tip_gripper"/>
    <child link="right_point_tip_gripper"/>
    <origin xyz="0 0 0.25" rpy="-0.6 0 0"/>
  </joint>

  <!-- Gazebo ROS2 Control Plugin -->
  <!-- <gazebo>
    <plugin name="gazebo_ros2_control" filename="libgazebo_ros2_control.so">
      <robot_namespace>/cobra</robot_namespace>
      <parameters>/home/aj/ros2_ws/src/cobrotic_moveit/config/ros2_controllers.yaml</parameters>
      <parameters>$(find cobrotic_moveit)/config/ros2_controllers.yaml</parameters>
    </plugin>
  </gazebo> -->

  <!-- ================== ROS2 Control ================== -->
  <!-- <ros2_control name="cobra" type="system">
    <hardware>
      <plugin>gazebo_ros2_control/DefaultRobotHWSim</plugin>
    </hardware>

    <joint name="bottom_to_pedestal">
      <command_interface name="position"/>
      <state_interface name="position"/>
    </joint>

    <joint name="pedestal_to_arm">
      <command_interface name="position"/>
      <state_interface name="position"/>
    </joint>

    <joint name="arm_to_forearm">
      <command_interface name="position"/>
      <state_interface name="position"/>
    </joint>

    <joint name="left_gripper_joint">
      <command_interface name="position"/>
      <state_interface name="position"/>
    </joint>

    <joint name="right_gripper_joint">
      <command_interface name="position"/>
      <state_interface name="position"/>
    </joint>

  </ros2_control> -->

  <!-- ================== ARM TRANSMISSIONS ================== -->
  <!-- <transmission name="bottom_to_pedestal_trans">
    <type>transmission_interface/SimpleTransmission</type>
    <joint name="bottom_to_pedestal">
      <hardwareInterface>hardware_interface/position</hardwareInterface>
    </joint>
    <actuator name="bottom_motor">
      <hardwareInterface>hardware_interface/position</hardwareInterface>
      <mechanicalReduction>1</mechanicalReduction>
    </actuator>
  </transmission>

  <transmission name="pedestal_to_arm_trans">
    <type>transmission_interface/SimpleTransmission</type>
    <joint name="pedestal_to_arm">
      <hardwareInterface>hardware_interface/position</hardwareInterface>
    </joint>
    <actuator name="arm_motor">
      <hardwareInterface>hardware_interface/position</hardwareInterface>
      <mechanicalReduction>1</mechanicalReduction>
    </actuator>
  </transmission>

  <transmission name="arm_to_forearm_trans">
    <type>transmission_interface/SimpleTransmission</type>
    <joint name="arm_to_forearm">
      <hardwareInterface>hardware_interface/position</hardwareInterface>
    </joint>
    <actuator name="forearm_motor">
      <hardwareInterface>hardware_interface/position</hardwareInterface>
      <mechanicalReduction>1</mechanicalReduction>
    </actuator>
  </transmission> -->

  <!-- ================== GRIPPER TRANSMISSIONS ================== -->
  <!-- <transmission name="left_gripper_joint_trans">
    <type>transmission_interface/SimpleTransmission</type>
    <joint name="left_gripper_joint">
      <hardwareInterface>hardware_interface/position</hardwareInterface>
    </joint>
    <actuator name="left_gripper_motor">
      <hardwareInterface>hardware_interface/position</hardwareInterface>
      <mechanicalReduction>1</mechanicalReduction>
    </actuator>
  </transmission>

  <transmission name="right_gripper_joint_trans">
    <type>transmission_interface/SimpleTransmission</type>
    <joint name="right_gripper_joint">
      <hardwareInterface>hardware_interface/position</hardwareInterface>
    </joint>
    <actuator name="right_gripper_motor">
      <hardwareInterface>hardware_interface/position</hardwareInterface>
      <mechanicalReduction>1</mechanicalReduction>
    </actuator>
  </transmission> -->

</robot>
