<?xml version="1.0"?>
<robot name="cobra">

  <!-- Mateirals -->
  <material name="blue">
    <color rgba="0 0 0.8 1"/>
  </material>

  <material name="yellow">
    <color rgba="1 0.7 0 1"/>
  </material>

  <!-- Base -->
  <link name="bottom">
    <visual>
      <origin xyz="0 0 0" rpy="0 0 0"/>
      <geometry>
        <box size="0.8 0.8 0.3"/>
      </geometry>
      <material name="blue">
      </material>
    </visual>
    <collision>
      <origin xyz="0 0 0" rpy="0 0 0"/>
      <geometry>
        <box size="0.8 0.8 0.3"/>
      </geometry>
    </collision>
    <inertial>
      <mass value="5.0"/>
      <origin xyz="0 0 0" rpy="0 0 0"/>
      <inertia ixx="0.1" iyy="0.1" izz="0.1" ixy="0" ixz="0" iyz="0"/>
    </inertial>
  </link>

  <!-- Pedestal -->
  <link name="pedestal">
    <visual>
      <origin xyz="0 0 0.3" rpy="0 0 0"/>
      <geometry>
        <box size="0.6 0.5 0.65"/>
      </geometry>
      <material name="blue">
      </material>
    </visual>
    <collision>
      <origin xyz="0 0 0.3" rpy="0 0 0"/>
      <geometry>
        <box size="0.6 0.5 0.65"/>
      </geometry>
    </collision>
    <inertial>
      <mass value="3.0"/>
      <origin xyz="0 0 0.325" rpy="0 0 0"/>
      <inertia ixx="0.05" iyy="0.05" izz="0.05" ixy="0" ixz="0" iyz="0"/>
    </inertial>
  </link>

  <joint name="bottom_to_pedestal" type="revolute">
    <axis xyz="0 0 1"/>
    <limit effort="1000.0" lower="0.0" upper="3.14" velocity="1.0"/>
    <parent link="bottom"/>
    <child link="pedestal"/>
    <origin xyz="0 0 0.25" rpy="0 0 0"/>
  </joint>

  <!-- Arm -->
  <link name="arm">
    <visual>
      <origin xyz="0 0.06 0.6" rpy="0 0 0"/>
      <geometry>
        <box size="0.4 0.5 1.6"/>
      </geometry>
      <material name="blue">
      </material>
    </visual>
    <collision>
      <origin xyz="0 0.06 0.6" rpy="0 0 0"/>
      <geometry>
        <box size="0.4 0.5 1.6"/>
      </geometry>
    </collision>
    <inertial>
      <mass value="4.0"/>
      <origin xyz="0 0.06 0.6" rpy="0 0 0"/>
      <inertia ixx="0.08" iyy="0.08" izz="0.08" ixy="0" ixz="0" iyz="0"/>
    </inertial>
  </link>

  <joint name="pedestal_to_arm" type="revolute">
  
    <axis xyz="0 1 0"/>
    <limit effort="1000.0" lower="0" upper="2.18166157" velocity="1.0"/>  
    <parent link="pedestal"/>
    <child link="arm"/>
    <origin rpy="0 -1.13446401 0" xyz="0 0 0.4"/>
  </joint>

  <!-- Forearm -->
  <link name="forearm">
    <visual>
      <origin xyz="-0.1 0 0.3" rpy="0 0 0"/>
      <geometry>
        <box size="0.4 0.5 1.25"/>
      </geometry>
      <material name="blue">
      </material>
    </visual>
    <collision>
      <origin xyz="-0.1 0 0.3" rpy="0 0 0"/>
      <geometry>
        <box size="0.4 0.5 1.25"/>
      </geometry>
    </collision>
    <inertial>
      <mass value="3.0"/>
      <origin xyz="-0.1 0 0.3" rpy="0 0 0"/>
      <inertia ixx="0.05" iyy="0.05" izz="0.05" ixy="0" ixz="0" iyz="0"/>
    </inertial>
  </link>

  <joint name="arm_to_forearm" type="revolute">
    <axis xyz="0 -1 0"/>
    <limit effort="1000.0" lower="0" upper="2.70526034" velocity="1.0"/>
    <parent link="arm"/>
    <child link="forearm"/>
    <origin rpy="0 2.70526034 0" xyz="0 0 1.2"/>
  </joint>

  <!-- Platform -->
  <link name="platform">
    <visual>
      <origin xyz="0 0 0" rpy="0 0 0"/>
      <geometry>
        <box size="0.03 0.5 0.5"/>
      </geometry>
      <material name="blue">
      </material>
    </visual>
    <collision>
      <origin xyz="0 0 0" rpy="0 0 0"/>
      <geometry>
        <box size="0.03 0.5 0.5"/>
      </geometry>
    </collision>
    <inertial>
      <mass value="0.5"/>
      <origin xyz="0 0 0.25" rpy="0 0 0"/>
      <inertia ixx="0.01" iyy="0.01" izz="0.01" ixy="0" ixz="0" iyz="0"/>
    </inertial>
  </link>

  <joint name="forearm_to_platform" type="fixed">
    <parent link="forearm"/>
    <child link="platform"/>
    <origin xyz="-0.2 0 0.6" rpy="0 0 0"/>
  </joint>

  <!-- Left Gripper -->
  <link name="left_gripper">
    <visual>
      <origin xyz="-0.1 -0.05 0.15" rpy="0 0 0"/>
      <geometry>
        <box size="0.03 0.1 0.6"/> 
      </geometry>
      <material name="yellow">
      </material>
    </visual>
    <collision>
      <geometry>
        <box size="0.03 0.1 0.6"/>
      </geometry>
    </collision>
  </link>

  <joint name="left_gripper_joint" type="revolute">
    <axis xyz="1 0 0"/>
    <limit effort="1000" lower="0" upper="0.523599" velocity="1.0"/>
    <parent link="platform"/>
    <child link="left_gripper"/>
    <origin xyz="-0.1 -0.15 0.15" rpy="0 0 0"/>
  </joint>

    <!-- Left Tip of Gripper -->
  <link name="left_tip_gripper">
    <visual>
      <origin xyz="0 0 0.12" rpy="0 0 0"/>
      <geometry>
        <box size="0.03 0.1 0.3"/> 
      </geometry>
      <material name="yellow">
      </material>
    </visual>
    <collision>
      <geometry>
        <box size="0.03 0.1 0.3"/>
      </geometry>
    </collision>
  </link>

  <joint name="left_tip_gripper_joint" type="fixed">
    <axis xyz="1 0 0"/>
    <parent link="left_gripper"/>
    <child link="left_tip_gripper"/>
    <origin xyz="-0.1 -0.05 0.45" rpy="-0.6 0 0"/>
  </joint>

      <!-- Left point of Tip -->
  <link name="left_point_tip_gripper">
    <visual>
      <origin xyz="0 0.005 0.04" rpy="0 0 0"/>
      <geometry>
        <box size="0.03 0.1 0.1"/> 
      </geometry>
      <material name="yellow">
      </material>
    </visual>
    <collision>
      <geometry>
        <box size="0.03 0.1 0.1"/>
      </geometry>
    </collision>
  </link>

  <joint name="left_point_tip_gripper_joint" type="fixed">
    <axis xyz="1 0 0"/>
    <parent link="left_tip_gripper"/>
    <child link="left_point_tip_gripper"/>
    <origin xyz="0 0 0.25" rpy="0.6 0 0"/>
  </joint>

  <!-- Right Gripper -->
  <link name="right_gripper">
    <visual>
      <origin xyz="-0.1 0.05 0.15" rpy="0 0 0"/>
      <geometry>
        <box size="0.03 0.1 0.6"/>
      </geometry>
      <material name="yellow">
      </material>
    </visual>
    <collision>
      <geometry>
        <box size="0.03 0.1 0.6"/>
      </geometry>
    </collision>
  </link>
  
  <joint name="right_gripper_joint" type="revolute">
    <axis xyz="-1 0 0"/>
    <limit effort="1000" lower="0" upper="0.523599" velocity="1.0"/>
    <parent link="platform"/>
    <child link="right_gripper"/>
    <origin xyz="-0.1 0.15 0.15" rpy="0 0 0"/>
  </joint>

    <!-- Right Tip of Gripper -->
  <link name="right_tip_gripper">
    <visual>
      <origin xyz="0 0 0.12" rpy="0 0 0"/>
      <geometry>
        <box size="0.03 0.1 0.3"/> 
      </geometry>
      <material name="yellow">
      </material>
    </visual>
    <collision>
      <geometry>
        <box size="0.03 0.1 0.3"/>
      </geometry>
    </collision>
  </link>

  <joint name="right_tip_gripper_joint" type="fixed">
    <axis xyz="1 0 0"/>
    <parent link="right_gripper"/>
    <child link="right_tip_gripper"/>
    <origin xyz="-0.1 0.05 0.45" rpy="0.6  0 0"/>
  </joint>

      <!-- Right point of Tip -->
  <link name="right_point_tip_gripper">
    <visual>
      <origin xyz="0 -0.005 0.04" rpy="0 0 0"/>
      <geometry>
        <box size="0.03 0.1 0.1"/> 
      </geometry>
      <material name="yellow">
      </material>
    </visual>
    <collision>
      <geometry>
        <box size="0.03 0.1 0.1"/>
      </geometry>
    </collision>
  </link>

  <joint name="right_point_tip_gripper_joint" type="fixed">
    <axis xyz="1 0 0"/>
    <parent link="right_tip_gripper"/>
    <child link="right_point_tip_gripper"/>
    <origin xyz="0 0 0.25" rpy="-0.6 0 0"/>
  </joint>

  <!-- Gazebo ROS2 Control Plugin -->
  <gazebo>
    <plugin name="gazebo_ros2_control" filename="libgazebo_ros2_control.so"/>
  </gazebo>

</robot>
