<?xml version="1.0"?>
<robot name="cobra">

  <link name="bottom">
    <visual>
      <geometry>
        <box size="0.8 0.8 0.3"/>
      </geometry>
    </visual>
  </link>

  <link name="pedestal">
    <visual>
      <geometry>
        <box size="0.6 0.5 0.65"/>
      </geometry>
      <origin rpy="0 0 0" xyz="0 0 0.3"/>
    </visual>
  </link>

  <joint name="bottom_to_pedestal" type="revolute">
    <axis xyz="0 0 1"/>
    <limit effort="1000.0" lower="0.00" upper="3.14" velocity="1.0"/>
    <parent link="bottom"/>
    <child link="pedestal"/>
    <origin xyz="0 0 0.25"/>
  </joint>

  <link name="arm">
    <visual>
      <geometry>
        <box size="0.40 0.50 1.60"/>
      </geometry>
      <origin rpy="0 0 0" xyz="0 0.06 0.6"/>
    </visual>
  </link>

  <joint name="pedestal_to_arm" type="revolute">
    <axis xyz="0 1 0"/>
    <limit effort="1000.0" lower="0" upper="2.18166157" velocity="1.0"/>  
    <parent link="pedestal"/>
    <child link="arm"/>
    <origin rpy="0 -1.13446401 0" xyz="0 0 0.4"/>
  </joint>

    <link name="forearm">
    <visual>
      <geometry>
        <box size="0.40 0.50 1.25"/>
      </geometry>
      <origin rpy="0 0 0" xyz="-0.1 0 0.3"/>
    </visual>
  </link>

  <joint name="arm_to_forearm" type="revolute">
    <axis xyz="0 -1 0"/>
    <limit effort="1000.0" lower="0" upper="2.70526034" velocity="1.0"/>
    <parent link="arm"/>
    <child link="forearm"/>
    <origin rpy="0 2.70526034 0" xyz="0 0 1.2"/>
  </joint>

  <link name="platform">
    <visual>
      <geometry>
        <box size="0.03 0.50 0.50"/>
      </geometry>
      <origin rpy="0 0 0" xyz="0 0 0"/>
    </visual>
  </link>

  <joint name="forearm_to_platform" type="fixed">
    <parent link="forearm"/>
    <child link="platform"/>
    <origin xyz="-0.2 0 0.6"/>
  </joint>

  <!-- Gripper -->
  <joint name="left_gripper_joint" type="revolute">
    <axis xyz="1 0 0"/>
    <limit effort="1000.0" lower="0" upper="0.523599" velocity="1.0"/>
    <origin rpy="0 0 0" xyz="-0.1 -0.08 0.15"/>
    <parent link="platform"/>
    <child link="left_gripper"/>
  </joint>

  <link name="left_gripper">
    <visual>
      <origin rpy="3.1415 -1.57 0" xyz="0 0 0"/>
      <geometry>
        <mesh filename="package://cobrotic/urdf/l_finger.dae"/>
      </geometry>
    </visual>
  </link>

  <joint name="left_tip_joint" type="fixed">
    <origin rpy="0 0 0" xyz="0 0 0.5"/>
    <parent link="left_gripper"/>
    <child link="left_tip"/>
  </joint>

  <link name="left_tip">
    <visual>
      <origin rpy="3.1415 -1.57 0" xyz="0 0 0"/>
      <geometry>
        <mesh filename="package://cobrotic/urdf/l_finger_tip.dae"/>
      </geometry>
    </visual>
  </link>

  <joint name="right_gripper_joint" type="revolute">
    <axis xyz="1 0 0"/>
    <limit effort="1000.0" lower="0.0" upper="0.523599" velocity="1.0"/>
    <origin rpy="0 0 3.1415" xyz="-0.1 0.08 0.15"/>
    <parent link="platform"/>
    <child link="right_gripper"/>
  </joint>

  <link name="right_gripper">
    <visual>
      <origin rpy="0 -1.57 3.1415" xyz="0 0 0"/>
      <geometry>
        <mesh filename="package://cobrotic/urdf/l_finger.dae"/>
      </geometry>
    </visual>
  </link>

  <joint name="right_tip_joint" type="fixed">
    <origin rpy="0 0 0" xyz="0 0 0.5"/>
    <parent link="right_gripper"/>
    <child link="right_tip"/>
  </joint>

  <link name="right_tip">
    <visual>
      <origin rpy="0 -1.57 3.1415" xyz="0 0 0"/>
      <geometry>
        <mesh filename="package://cobrotic/urdf/l_finger_tip.dae"/>
      </geometry>
    </visual>
  </link>

  <gazebo>
    <plugin name="gazebo_ros2_control" filename="libgazebo_ros2_control.so"/>
  </gazebo>

</robot>